<?xml version="1.0" encoding="utf-8"?>
<robot name="wheeldiffdrive">


  <!--                    DEFINING MATERIALS   -->
  <material name="blue">
    <color rgba="0 0 1 1" />
  </material>

  <material name="white">
    <color rgba="1 1 1 1" />
  </material>
  <material name="red">
    <color rgba=" 0.5 0.2 0.8 1" />
  </material>

  <!--Defining
  the robot-->
  <!--                      BASE LINK            -->
  <link
    name="base_link">
    <inertial>
      <origin
        xyz="0.215897452397763 -0.466115278224488 -0.406633769007423"
        rpy="0 0 0" />
      <mass
        value="30.16212370053717" />
      <inertia
        ixx="0.308297541964297"
        ixy="-3.58520428121968E-07"
        ixz="4.87684354694172E-06"
        iyy="0.323504290432657"
        iyz="-0.0485683019754604"
        izz="0.281374166804536" />
    </inertial>
    <visual>
      <origin
        xyz="0 0 0"
        rpy="0 0 -1.570796" />
      <geometry>
        <mesh
          filename="package://project_ws/meshes/chair_link.STL" />
      </geometry>
      <material
        name="">
        <color
          rgba="1 1 1 1" />
      </material>
    </visual>
    <collision>
      <origin
        xyz="0 0 0"
        rpy="0 0 0" />
      <geometry>
        <mesh
          filename="package://project_ws/meshes/chair_link.STL" />
      </geometry>
    </collision>
  </link>
  <gazebo reference="base_link">
    <material>Gazebo/Blue</material>
  </gazebo>


  <!--                      BASE FOOTPRINT            -->
  <link
    name="base_footprint">
    <inertial>
      <origin
        xyz="0.215897452397763 -0.466115278224488 -0.406633769007423"
        rpy="0 0 0" />
      <mass
        value="10.16212370053717" />
      <inertia
        ixx="0.308297541964297"
        ixy="-3.58520428121968E-07"
        ixz="4.87684354694172E-06"
        iyy="0.323504290432657"
        iyz="-0.0485683019754604"
        izz="0.281374166804536" />
    </inertial>

    
  </link>
  <gazebo reference="base_footprint">
    <material>Gazebo/Blue</material>
  </gazebo>

  <!--           JOINT BASE TO RIGHT FRONT WHEEL  -->
  <joint name="joint_base_to_footprint" type="fixed">
    <origin
      xyz="-0.15 0.2  0.58"
      rpy="0 0 0" /><!--0.4318
    0.55563-->
    <axis xyz="1 0 0" rpy="0 0 0" />
    <parent link="base_footprint" />
    <child link="base_link" />
  </joint>

  


  <!--                    RIGHT FRONT WHEEL                       -->
  <link
    name="right_front_wheel">
    <inertial>
      <origin
        xyz="3.68982622234171E-13 0 0"
        rpy="0 0 0" />
      <mass
        value="3.59127347260337" />
      <inertia
        ixx="0.00171792777524043"
        ixy="2.83050865876848E-20"
        ixz="-1.13478840286474E-19"
        iyy="0.000880037934920852"
        iyz="2.19202862326551E-20"
        izz="0.000880037934920852" />
    </inertial>
    <visual>
      <origin
        xyz="0 0 0"
        rpy="0 0 0" />
      <geometry>
        <mesh
          filename="package://project_ws/meshes/right_front_wheel_link.STL" />
      </geometry>
      <material
        name="">
        <color
          rgba="0.796078431372549 0.823529411764706 0.937254901960784 1" />
      </material>
    </visual>
    <collision>
      <origin
        xyz="0 0 0"
        rpy="0 0 0" />
      <geometry>
        <mesh
          filename="package://project_ws/meshes/right_front_wheel_link.STL" />
      </geometry>
    </collision>
  </link>
  <gazebo reference="right_front_wheel">
    <material>Gazebo/White</material>
  </gazebo>
  
  <!--           JOINT BASE TO RIGHT FRONT WHEEL  -->
  <joint name="joint_base_to_right_front_wheel" type="continuous">
    <origin
      xyz="0.42 -0.28 -0.22"
      rpy="0 0 1.570796" /><!--0.4318
    0.55563-->
    <axis xyz="1 0 0" rpy="0 0 0" />
    <parent link="base_footprint" />
    <child link="right_front_wheel" />
  </joint>

  <!--                    LEFT FRONT WHEEL                       -->
  <link
    name="left_front_wheel">
    <inertial>
      <origin
        xyz="3.68919128075658E-13 1.11022302462516E-16 -1.11022302462516E-16"
        rpy="0 0 0" />
      <mass
        value="3.59127347260337" />
      <inertia
        ixx="0.00171792777524043"
        ixy="2.83050865876848E-20"
        ixz="-1.13478840286474E-19"
        iyy="0.000880037934920852"
        iyz="2.19202862326551E-20"
        izz="0.000880037934920852" />
    </inertial>
    <visual>
      <origin
        xyz="0 0 0"
        rpy="0 0 0" />
      <geometry>
        <mesh
          filename="package://project_ws/meshes/left_front_wheel_link.STL" />
      </geometry>
      <material
        name="">
        <color
          rgba="0.796078431372549 0.823529411764706 0.937254901960784 1" />
      </material>
    </visual>
    <collision>
      <origin
        xyz="0 0 0"
        rpy="0 0 0" />
      <geometry>
        <mesh
          filename="package://project_ws/meshes/left_front_wheel_link.STL" />
      </geometry>
    </collision>
  </link>
  <gazebo reference="left_front_wheel">
    <material>Gazebo/White</material>
  </gazebo>

  <!--           JOINT BASE TO LEFT FRONT WHEEL  -->

  <joint name="joint_base_to_left_front_wheel" type="continuous">
    <origin
      xyz="0.42 0.28 -0.22"
      rpy="0 0 1.570796" />
    <axis xyz="1 0 0" rpy="0 0 0" />
    <parent link="base_footprint" />
    <child link="left_front_wheel" />
  </joint>


  <!--                    RIGHT BACK WHEEL                       -->
  <link
    name="right_back_wheel">
    <inertial>
      <origin
        xyz="0.0469427212195542 0 5.55111512312578E-17"
        rpy="0 0 0" />
      <mass
        value="5.09127347260337" />
      <inertia
        ixx="0.141718020445608"
        ixy="2.73584332854114E-18"
        ixz="-4.77994102978222E-18"
        iyy="0.0710324578470619"
        iyz="2.49366499671666E-17"
        izz="0.0710324578470619" />
    </inertial>
    <visual>
      <origin
        xyz="0 0 0"
        rpy="0 0 0" />
      <geometry>
        <mesh
          filename="package://project_ws/meshes/right_back_wheel_link.STL" />
      </geometry>
      <material
        name="">
        <color
          rgba="0.796078431372549 0.823529411764706 0.937254901960784 1" />
      </material>
    </visual>
    <collision>
      <origin
        xyz="0 0 0"
        rpy="0 0 0" />
      <geometry>
        <mesh
          filename="package://project_ws/meshes/right_back_wheel_link.STL" />
      </geometry>
    </collision>
  </link>
  <gazebo reference="right_back_wheel">
    <material>Gazebo/White</material>
  </gazebo>

  <!--           JOINT BASE TO RIGHT BACK WHEEL  -->
  <joint name="joint_base_to_right_back_wheel" type="continuous">
    <origin
      xyz="0 -0.254 0"
      rpy="0 0 -1.570796" />
    <axis xyz="-1 0 0" rpy="0 0 0" />
    <parent link="base_footprint" />
    <child link="right_back_wheel" />
    <limit effort="100" velocity="100"/>
    <joint_properties damping="0.0" friction="0.0"/>
  </joint>

  <!--                    LEFT BACK WHEEL                       -->
  <link
    name="left_back_wheel">
    <inertial>
      <origin
        xyz="0.0469427212195542 5.55111512312578E-17 0"
        rpy="0 0 0" />
      <mass
        value="5.09127347260337" />
      <inertia
        ixx="0.141718020445608"
        ixy="2.73584332854114E-18"
        ixz="-4.77994102978222E-18"
        iyy="0.0710324578470619"
        iyz="2.49366499671666E-17"
        izz="0.0710324578470619" />
    </inertial>
    <visual>
      <origin
        xyz="0 0 0"
        rpy="0 0 0" />
      <geometry>
        <mesh
          filename="package://project_ws/meshes/left_back_wheel_link.STL" />
      </geometry>
      <material
        name="">
        <color
          rgba="0.796078431372549 0.823529411764706 0.937254901960784 1" />
      </material>
    </visual>
    <collision>
      <origin
        xyz="0 0 0"
        rpy="0 0 0" />
      <geometry>
        <mesh
          filename="package://project_ws/meshes/left_back_wheel_link.STL" />
      </geometry>
    </collision>
  </link>
  <gazebo reference="left_back_wheel">
    <material>Gazebo/White</material>
  </gazebo>

  <!--           JOINT BASE TO LEFT BACK WHEEL    -->
  <joint name="joint_base_to_left_back_wheel" type="continuous">
    <origin
      xyz="0 0.254 0"
      rpy="0 0 1.570796" />
    <axis xyz="1 0 0" rpy="0 0 0" />
    <parent link="base_footprint" />
    <child link="left_back_wheel" />
    <limit effort="100" velocity="100"/>
    <joint_properties damping="0.0" friction="0.0"/>
  </joint>

  <!--                    LASER LINK                       -->

  <link name="laser_link">
    <inertial>
      <mass value="0.1" />
      <inertia ixx="1" ixy="0" ixz="0" iyy="1" iyz="0" izz="1" />
    </inertial>

    <visual>

      <geometry>
        <box size="0.02 0.02 0.02" />
      </geometry>
      <material name="green">
      </material>
    </visual>

    <collision>

      <geometry>
        <box size="0.02 0.02 0.02" />
      </geometry>
    </collision>
  </link>

  <gazebo reference="laser_link">
    <material>Gazebo/Red</material>
  </gazebo>

  <!--                    JOINT TO LASER                       -->

  <joint name="joint_base_to_laser_link" type="fixed">
    <origin xyz="0.09 -0.2 0.45" rpy="0 0 0 " />
    <parent link="base_link" />
    <child link="laser_link" />
  </joint>

  <!--                    CAMERA LINK                     -->
  <link name="camera_link">
    <inertial>
      <mass value="0.1" />
      <inertia ixx="1" ixy="0" ixz="0" iyy="1" iyz="0" izz="1" />
    </inertial>

    <visual>

      <geometry>
        <box size="0.01 0.01 0.01" />
      </geometry>
      <material name="green">
      </material>
    </visual>

    <collision>

      <geometry>
        <box size="0.01 0.01 0.01" />
      </geometry>
    </collision>
  </link>

  <gazebo reference="camera_link">
    <material>Gazebo/Red</material>
  </gazebo>


  <!--           JOINT BASE TO CAMERA    -->
  <joint name="joint_base_to_camera_link" type="fixed">
    <origin xyz="0.0 0.0 0.05" rpy="1.57 0 0" />
    <parent link="camera_holder" />
    <child link="camera_link" />
  </joint>

  <joint name="camera_holder_joint" type="fixed">
    <parent link="base_footprint"/>
    <child link="camera_holder"/>
    <origin xyz="0.4 -0.025 -0.2" rpy ="0 0 0"/>
  </joint>

  <link name="depth_camera_optical">
  </link>
  
  <joint name="depth_camera_optical_joint" type="fixed">
    <axis xyz="0 1 0" />
    <origin xyz="0 0 0" rpy="-1.57 0 -1.57"/>
    <parent link="camera_link"/>
    <child link="depth_camera_optical"/>
  </joint>

  <!--       MAN LINK        -->
  <link
    name="man_sitting_link">
    <inertial>
      <origin
        xyz="-3.179E-05 -0.11481 -0.1411"
        rpy="0 0 0" />
      <mass
        value="40" />
      <inertia
        ixx="13.785"
        ixy="-0.012446"
        ixz="-0.0029163"
        iyy="12.533"
        iyz="3.4808"
        izz="4.9919" />
    </inertial>
    <visual>
      <origin
        xyz="0 0 0"
        rpy="1.5707963267949 0 0" />
      <geometry>
        <mesh
          filename="package://project_ws/meshes/Man_Sitting.STL" />
      </geometry>
      <material
        name="">
        <color
          rgba="0.79216 0.81961 0.93333 1" />
      </material>
    </visual>
    <collision>
      <origin
        xyz="0 0 0"
        rpy="1.5707963267949 0 0" />
      <geometry>
        <mesh
          filename="package://project_ws/meshes/Man_Sitting.STL" />
      </geometry>
    </collision>
  </link>
  <gazebo reference="man_sitting">
    <material>Gazebo/Pink</material>
  </gazebo>

  <!--     JOINT MAN          -->

  <joint name="man_sitting_joint" type="fixed">
    <parent link="base_link" />
    <child link="man_sitting_link" />
    <origin xyz="0.22 -0.22 -0.07" rpy="0 0 -4.712 " />
  </joint>


  <!--       LASER HOLDER        -->

  <link name="laser_holder">
    <visual>
      <geometry>
        <box size="0.4 0.025 0.025" />
      </geometry>
      <origin rpy="0 1.57075 0" xyz="0 0 -0.3" />
      <material name="white" />
    </visual>
    <collision>
      <geometry>
        <box size="0.4 0.025 0.025" />
      </geometry>
      <origin rpy="0 1.57075 0" xyz="0 0 -0.3" />
    </collision>
    <inertial>
      <mass value="0.01" />
      <inertia ixx="1.0" ixy="0.0" ixz="0.0" iyy="1.0" iyz="0.0" izz="1.0" />
    </inertial>
  </link>
  <gazebo reference="laser_holder">
    <material>Gazebo/Blue</material>
  </gazebo>

  <!--     JOINT BASE TO LASER HOLDER         -->

  <joint name="laser_holder_joint" type="fixed">
    <parent link="base_link" />
    <child link="laser_holder" />
    <origin xyz="0.09 -0.2 0.45" rpy="0 0 -1.570796" />
  </joint>

  <!--       CAMERA HOLDER        -->
  <link name="camera_holder">
    <visual>
      <geometry>
        <box size="0.2 0.05 0.05" />
      </geometry>
      <material name="white" />
    </visual>
    <collision>
      <geometry>
        <box size="0.2 0.05 0.05" />
      </geometry>
    </collision>
    <inertial>
      <mass value="0.01" />
      <inertia ixx="1.0" ixy="0.0" ixz="0.0" iyy="1.0" iyz="0.0" izz="1.0" />
    </inertial>
  </link>
  <gazebo reference="camera_holder">
    <material>Gazebo/Blue</material>
  </gazebo>

  <!--     JOINT BASE TO CAMERA HOLDER         -->

  

  <!--       CAMERA HOLDER 2        -->

  <link name="camera_holder_two">
    <visual>
      <geometry>
        <box size="0.30 0.01 0.01" />
      </geometry>
      <origin rpy="0 1.57075 0" xyz="0 0 -0.3" />
      <material name="white" />
    </visual>
    <collision>
      <geometry>
        <box size="0.30 0.01 0.01" />
      </geometry>
      <origin rpy="0 1.57075 0" xyz="0 0 -0.3" />
    </collision>
    <inertial>
      <mass value="0.01" />
      <inertia ixx="1.0" ixy="0.0" ixz="0.0" iyy="1.0" iyz="0.0" izz="1.0" />
    </inertial>
  </link>
  <gazebo reference="camera_holder_two">
    <material>Gazebo/Blue</material>
  </gazebo>

  <!--     JOINT BASE TO CAMERA HOLDER 2         -->

  <joint name="camera_holder_two_joint" type="fixed">
    <parent link="camera_holder" />
    <child link="camera_holder_two" />
    <origin xyz="-0.01 0.020 0.43" rpy="0 0 -1.570796" />
  </joint>


  <!--                       ROS CONTROL      -->
  <gazebo>
    <plugin name="skid_steer_drive_controller" filename="libgazebo_ros_skid_steer_drive.so">
      <updateRate>100.0</updateRate>
      <robotNamespace>vehiclediffdrive</robotNamespace>
      <leftFrontJoint>joint_base_to_left_front_wheel</leftFrontJoint>
      <rightFrontJoint>joint_base_to_right_front_wheel</rightFrontJoint>
      <leftRearJoint>joint_base_to_left_back_wheel</leftRearJoint>
      <rightRearJoint>joint_base_to_right_back_wheel</rightRearJoint>
      <wheelSeparation>0.48</wheelSeparation>
      <wheelDiameter>0.56</wheelDiameter>
      <robotBaseFrame>base_footprint</robotBaseFrame>
      <publishWheelTF>true</publishWheelTF>
      <publishWheelJointState>true</publishWheelJointState>
      <torque>30</torque>
      <commandTopic>cmd_vel</commandTopic>
      <broadcastTF>true</broadcastTF>
      <odometrySource>world</odometrySource>
    </plugin>
  </gazebo>

  <!-- <gazebo>
    <plugin name="differential_drive_controller" filename="libgazebo_ros_diff_drive.so">
     <robotNamespace>vehiclediffdrive</robotNamespace>
      <legacyMode>false</legacyMode>
      <alwaysOn>true</alwaysOn>
      <updateRate>100</updateRate>
      <leftJoint>joint_base_to_left_back_wheel</leftJoint>
      <rightJoint>joint_base_to_right_back_wheel</rightJoint>
      <wheelSeparation>0.48</wheelSeparation>
      <wheelDiameter>0.56</wheelDiameter>
      <torque>80</torque>
      <commandTopic>cmd_vel</commandTopic>
      <odometryTopic>odom</odometryTopic>
      <odometryFrame>odom</odometryFrame>
      <odometrySource>1</odometrySource>

      <robotBaseFrame>base_footprint</robotBaseFrame>
    </plugin>
  </gazebo> -->


  <!--                        LASER PLUGIN                  -->

  <gazebo reference="laser_link">
    <sensor type="ray" name="head_hokuyo_sensor">
      <pose>0 0 0 0 0 0</pose>
      <visualize>false</visualize>
      <update_rate>40</update_rate>
      <ray>
        <scan>
          <horizontal>
            <samples>720</samples>
            <resolution>1</resolution>
            <min_angle>-3.14160796</min_angle>
            <max_angle>3.14160796</max_angle>
          </horizontal>
        </scan>
        <range>
          <min>0.10</min>
          <max>15.0</max>
          <resolution>0.01</resolution>
        </range>
        <noise>
          <type>gaussian</type>

          <mean>0.0</mean>
          <stddev>0.01</stddev>
        </noise>
      </ray>
      <plugin name="gazebo_ros_head_hokuyo_controller" filename="libgazebo_ros_laser.so">
        <topicName>/vehiclediffdrive/laser/scan</topicName>
        <frameName>laser_link</frameName>
      </plugin>
    </sensor>
  </gazebo>

  <!--                    CAMERA  PLUGIN                 -->
  <gazebo reference="camera_link">
    <sensor type="depth" name="camera">
      <always_on>true</always_on>
      <visualize>true</visualize>
      <camera>
        <horizontal_fov>1.047</horizontal_fov>
        <image>
          <width>640</width>
          <height>480</height>
          <format>R8G8B8</format>
        </image>
        <depth_camera>

        </depth_camera>
        <clip>
          <near>0.1</near>
          <far>100</far>
        </clip>
      </camera>
      <plugin name="camera_controller" filename="libgazebo_ros_openni_kinect.so">
        <baseline>0.2</baseline>
        <alwaysOn>true</alwaysOn>
        <updateRate>10.0</updateRate>
        <cameraName>camera</cameraName>
        <frameName>depth_camera_optical</frameName>
        <imageTopicName>rgb/image_raw</imageTopicName>
        <depthImageTopicName>depth/image_raw</depthImageTopicName>
        <pointCloudTopicName>depth/points</pointCloudTopicName>
        <cameraInfoTopicName>rgb/camera_info</cameraInfoTopicName>
        <depthImageCameraInfoTopicName>depth/camera_info</depthImageCameraInfoTopicName>
        <pointCloudCutoff>0.4</pointCloudCutoff>
        <hackBaseline>0.07</hackBaseline>
        <distortionK1>0.0</distortionK1>
        <distortionK2>0.0</distortionK2>
        <distortionK3>0.0</distortionK3>
        <distortionT1>0.0</distortionT1>
        <distortionT2>0.0</distortionT2>
        <CxPrime>0.0</CxPrime>
        <Cx>0.0</Cx>
        <Cy>0.0</Cy>
        <focalLength>0.0</focalLength>
      </plugin>
    </sensor>
  </gazebo>

</robot>